2019-12-07 15:46:43,491 ERROR: Exception on / [GET] [in /home/honery/Documents/cursach/.env/lib/python3.7/site-packages/flask/app.py:1891]
Traceback (most recent call last):
  File "/home/honery/Documents/cursach/.env/lib/python3.7/site-packages/flask/app.py", line 2446, in wsgi_app
    response = self.full_dispatch_request()
  File "/home/honery/Documents/cursach/.env/lib/python3.7/site-packages/flask/app.py", line 1951, in full_dispatch_request
    rv = self.handle_user_exception(e)
  File "/home/honery/Documents/cursach/.env/lib/python3.7/site-packages/flask/app.py", line 1820, in handle_user_exception
    reraise(exc_type, exc_value, tb)
  File "/home/honery/Documents/cursach/.env/lib/python3.7/site-packages/flask/_compat.py", line 39, in reraise
    raise value
  File "/home/honery/Documents/cursach/.env/lib/python3.7/site-packages/flask/app.py", line 1947, in full_dispatch_request
    rv = self.preprocess_request()
  File "/home/honery/Documents/cursach/.env/lib/python3.7/site-packages/flask/app.py", line 2241, in preprocess_request
    rv = func()
  File "/home/honery/Documents/cursach/app/routes.py", line 110, in before_request
    if current_user.is_authenticated:
  File "/home/honery/Documents/cursach/.env/lib/python3.7/site-packages/werkzeug/local.py", line 348, in __getattr__
    return getattr(self._get_current_object(), name)
  File "/home/honery/Documents/cursach/.env/lib/python3.7/site-packages/werkzeug/local.py", line 307, in _get_current_object
    return self.__local()
  File "/home/honery/Documents/cursach/.env/lib/python3.7/site-packages/flask_login/utils.py", line 26, in <lambda>
    current_user = LocalProxy(lambda: _get_user())
  File "/home/honery/Documents/cursach/.env/lib/python3.7/site-packages/flask_login/utils.py", line 335, in _get_user
    current_app.login_manager._load_user()
  File "/home/honery/Documents/cursach/.env/lib/python3.7/site-packages/flask_login/login_manager.py", line 359, in _load_user
    return self.reload_user()
  File "/home/honery/Documents/cursach/.env/lib/python3.7/site-packages/flask_login/login_manager.py", line 321, in reload_user
    user = self.user_callback(user_id)
  File "/home/honery/Documents/cursach/app/models.py", line 96, in load_user
    return User.query.get(int(id))
  File "/home/honery/Documents/cursach/.env/lib/python3.7/site-packages/flask_sqlalchemy/__init__.py", line 517, in __get__
    mapper = orm.class_mapper(type)
  File "/home/honery/Documents/cursach/.env/lib/python3.7/site-packages/sqlalchemy/orm/base.py", line 441, in class_mapper
    mapper = _inspect_mapped_class(class_, configure=configure)
  File "/home/honery/Documents/cursach/.env/lib/python3.7/site-packages/sqlalchemy/orm/base.py", line 420, in _inspect_mapped_class
    mapper._configure_all()
  File "/home/honery/Documents/cursach/.env/lib/python3.7/site-packages/sqlalchemy/orm/mapper.py", line 1337, in _configure_all
    configure_mappers()
  File "/home/honery/Documents/cursach/.env/lib/python3.7/site-packages/sqlalchemy/orm/mapper.py", line 3248, in configure_mappers
    mapper._post_configure_properties()
  File "/home/honery/Documents/cursach/.env/lib/python3.7/site-packages/sqlalchemy/orm/mapper.py", line 1947, in _post_configure_properties
    prop.init()
  File "/home/honery/Documents/cursach/.env/lib/python3.7/site-packages/sqlalchemy/orm/interfaces.py", line 196, in init
    self.do_init()
  File "/home/honery/Documents/cursach/.env/lib/python3.7/site-packages/sqlalchemy/orm/relationships.py", line 1864, in do_init
    self._generate_backref()
  File "/home/honery/Documents/cursach/.env/lib/python3.7/site-packages/sqlalchemy/orm/relationships.py", line 2073, in _generate_backref
    % (backref_key, self, m)
sqlalchemy.exc.ArgumentError: Error creating backref 'author' on relationship 'Post.answers': property of that name exists on mapper 'mapped class Answer->answer'
2019-12-07 15:46:45,153 ERROR: Exception on / [GET] [in /home/honery/Documents/cursach/.env/lib/python3.7/site-packages/flask/app.py:1891]
Traceback (most recent call last):
  File "/home/honery/Documents/cursach/.env/lib/python3.7/site-packages/flask/app.py", line 2446, in wsgi_app
    response = self.full_dispatch_request()
  File "/home/honery/Documents/cursach/.env/lib/python3.7/site-packages/flask/app.py", line 1951, in full_dispatch_request
    rv = self.handle_user_exception(e)
  File "/home/honery/Documents/cursach/.env/lib/python3.7/site-packages/flask/app.py", line 1820, in handle_user_exception
    reraise(exc_type, exc_value, tb)
  File "/home/honery/Documents/cursach/.env/lib/python3.7/site-packages/flask/_compat.py", line 39, in reraise
    raise value
  File "/home/honery/Documents/cursach/.env/lib/python3.7/site-packages/flask/app.py", line 1947, in full_dispatch_request
    rv = self.preprocess_request()
  File "/home/honery/Documents/cursach/.env/lib/python3.7/site-packages/flask/app.py", line 2241, in preprocess_request
    rv = func()
  File "/home/honery/Documents/cursach/app/routes.py", line 110, in before_request
    if current_user.is_authenticated:
  File "/home/honery/Documents/cursach/.env/lib/python3.7/site-packages/werkzeug/local.py", line 348, in __getattr__
    return getattr(self._get_current_object(), name)
  File "/home/honery/Documents/cursach/.env/lib/python3.7/site-packages/werkzeug/local.py", line 307, in _get_current_object
    return self.__local()
  File "/home/honery/Documents/cursach/.env/lib/python3.7/site-packages/flask_login/utils.py", line 26, in <lambda>
    current_user = LocalProxy(lambda: _get_user())
  File "/home/honery/Documents/cursach/.env/lib/python3.7/site-packages/flask_login/utils.py", line 335, in _get_user
    current_app.login_manager._load_user()
  File "/home/honery/Documents/cursach/.env/lib/python3.7/site-packages/flask_login/login_manager.py", line 359, in _load_user
    return self.reload_user()
  File "/home/honery/Documents/cursach/.env/lib/python3.7/site-packages/flask_login/login_manager.py", line 321, in reload_user
    user = self.user_callback(user_id)
  File "/home/honery/Documents/cursach/app/models.py", line 96, in load_user
    return User.query.get(int(id))
  File "/home/honery/Documents/cursach/.env/lib/python3.7/site-packages/flask_sqlalchemy/__init__.py", line 517, in __get__
    mapper = orm.class_mapper(type)
  File "/home/honery/Documents/cursach/.env/lib/python3.7/site-packages/sqlalchemy/orm/base.py", line 441, in class_mapper
    mapper = _inspect_mapped_class(class_, configure=configure)
  File "/home/honery/Documents/cursach/.env/lib/python3.7/site-packages/sqlalchemy/orm/base.py", line 420, in _inspect_mapped_class
    mapper._configure_all()
  File "/home/honery/Documents/cursach/.env/lib/python3.7/site-packages/sqlalchemy/orm/mapper.py", line 1337, in _configure_all
    configure_mappers()
  File "/home/honery/Documents/cursach/.env/lib/python3.7/site-packages/sqlalchemy/orm/mapper.py", line 3244, in configure_mappers
    raise e
sqlalchemy.exc.InvalidRequestError: One or more mappers failed to initialize - can't proceed with initialization of other mappers. Triggering mapper: 'mapped class Post->post'. Original exception was: Error creating backref 'author' on relationship 'Post.answers': property of that name exists on mapper 'mapped class Answer->answer'
