2019-12-07 16:53:39,732 ERROR: Exception on / [GET] [in /home/honery/Documents/cursach/.env/lib/python3.7/site-packages/flask/app.py:1891]
Traceback (most recent call last):
  File "/home/honery/Documents/cursach/.env/lib/python3.7/site-packages/sqlalchemy/engine/base.py", line 1249, in _execute_context
    cursor, statement, parameters, context
  File "/home/honery/Documents/cursach/.env/lib/python3.7/site-packages/sqlalchemy/engine/default.py", line 580, in do_execute
    cursor.execute(statement, parameters)
psycopg2.errors.UndefinedColumn: column user.about_me does not exist
LINE 1: ...mail, "user".password_hash AS user_password_hash, "user".abo...
                                                             ^


The above exception was the direct cause of the following exception:

Traceback (most recent call last):
  File "/home/honery/Documents/cursach/.env/lib/python3.7/site-packages/flask/app.py", line 2446, in wsgi_app
    response = self.full_dispatch_request()
  File "/home/honery/Documents/cursach/.env/lib/python3.7/site-packages/flask/app.py", line 1951, in full_dispatch_request
    rv = self.handle_user_exception(e)
  File "/home/honery/Documents/cursach/.env/lib/python3.7/site-packages/flask/app.py", line 1820, in handle_user_exception
    reraise(exc_type, exc_value, tb)
  File "/home/honery/Documents/cursach/.env/lib/python3.7/site-packages/flask/_compat.py", line 39, in reraise
    raise value
  File "/home/honery/Documents/cursach/.env/lib/python3.7/site-packages/flask/app.py", line 1947, in full_dispatch_request
    rv = self.preprocess_request()
  File "/home/honery/Documents/cursach/.env/lib/python3.7/site-packages/flask/app.py", line 2241, in preprocess_request
    rv = func()
  File "/home/honery/Documents/cursach/app/routes.py", line 110, in before_request
    if current_user.is_authenticated:
  File "/home/honery/Documents/cursach/.env/lib/python3.7/site-packages/werkzeug/local.py", line 348, in __getattr__
    return getattr(self._get_current_object(), name)
  File "/home/honery/Documents/cursach/.env/lib/python3.7/site-packages/werkzeug/local.py", line 307, in _get_current_object
    return self.__local()
  File "/home/honery/Documents/cursach/.env/lib/python3.7/site-packages/flask_login/utils.py", line 26, in <lambda>
    current_user = LocalProxy(lambda: _get_user())
  File "/home/honery/Documents/cursach/.env/lib/python3.7/site-packages/flask_login/utils.py", line 335, in _get_user
    current_app.login_manager._load_user()
  File "/home/honery/Documents/cursach/.env/lib/python3.7/site-packages/flask_login/login_manager.py", line 359, in _load_user
    return self.reload_user()
  File "/home/honery/Documents/cursach/.env/lib/python3.7/site-packages/flask_login/login_manager.py", line 321, in reload_user
    user = self.user_callback(user_id)
  File "/home/honery/Documents/cursach/app/models.py", line 96, in load_user
    return User.query.get(int(id))
  File "/home/honery/Documents/cursach/.env/lib/python3.7/site-packages/sqlalchemy/orm/query.py", line 959, in get
    return self._get_impl(ident, loading.load_on_pk_identity)
  File "/home/honery/Documents/cursach/.env/lib/python3.7/site-packages/sqlalchemy/orm/query.py", line 1069, in _get_impl
    return db_load_fn(self, primary_key_identity)
  File "/home/honery/Documents/cursach/.env/lib/python3.7/site-packages/sqlalchemy/orm/loading.py", line 282, in load_on_pk_identity
    return q.one()
  File "/home/honery/Documents/cursach/.env/lib/python3.7/site-packages/sqlalchemy/orm/query.py", line 3300, in one
    ret = self.one_or_none()
  File "/home/honery/Documents/cursach/.env/lib/python3.7/site-packages/sqlalchemy/orm/query.py", line 3269, in one_or_none
    ret = list(self)
  File "/home/honery/Documents/cursach/.env/lib/python3.7/site-packages/sqlalchemy/orm/query.py", line 3342, in __iter__
    return self._execute_and_instances(context)
  File "/home/honery/Documents/cursach/.env/lib/python3.7/site-packages/sqlalchemy/orm/query.py", line 3367, in _execute_and_instances
    result = conn.execute(querycontext.statement, self._params)
  File "/home/honery/Documents/cursach/.env/lib/python3.7/site-packages/sqlalchemy/engine/base.py", line 988, in execute
    return meth(self, multiparams, params)
  File "/home/honery/Documents/cursach/.env/lib/python3.7/site-packages/sqlalchemy/sql/elements.py", line 287, in _execute_on_connection
    return connection._execute_clauseelement(self, multiparams, params)
  File "/home/honery/Documents/cursach/.env/lib/python3.7/site-packages/sqlalchemy/engine/base.py", line 1107, in _execute_clauseelement
    distilled_params,
  File "/home/honery/Documents/cursach/.env/lib/python3.7/site-packages/sqlalchemy/engine/base.py", line 1253, in _execute_context
    e, statement, parameters, cursor, context
  File "/home/honery/Documents/cursach/.env/lib/python3.7/site-packages/sqlalchemy/engine/base.py", line 1473, in _handle_dbapi_exception
    util.raise_from_cause(sqlalchemy_exception, exc_info)
  File "/home/honery/Documents/cursach/.env/lib/python3.7/site-packages/sqlalchemy/util/compat.py", line 398, in raise_from_cause
    reraise(type(exception), exception, tb=exc_tb, cause=cause)
  File "/home/honery/Documents/cursach/.env/lib/python3.7/site-packages/sqlalchemy/util/compat.py", line 152, in reraise
    raise value.with_traceback(tb)
  File "/home/honery/Documents/cursach/.env/lib/python3.7/site-packages/sqlalchemy/engine/base.py", line 1249, in _execute_context
    cursor, statement, parameters, context
  File "/home/honery/Documents/cursach/.env/lib/python3.7/site-packages/sqlalchemy/engine/default.py", line 580, in do_execute
    cursor.execute(statement, parameters)
sqlalchemy.exc.ProgrammingError: (psycopg2.errors.UndefinedColumn) column user.about_me does not exist
LINE 1: ...mail, "user".password_hash AS user_password_hash, "user".abo...
                                                             ^

[SQL: SELECT "user".id AS user_id, "user".username AS user_username, "user".email AS user_email, "user".password_hash AS user_password_hash, "user".about_me AS user_about_me, "user".last_seen AS user_last_seen 
FROM "user" 
WHERE "user".id = %(param_1)s]
[parameters: {'param_1': 3}]
(Background on this error at: http://sqlalche.me/e/f405)
2019-12-07 16:53:56,075 INFO: Microblog startup [in /home/honery/Documents/cursach/app/__init__.py:33]
2019-12-07 16:54:00,646 INFO: Microblog startup [in /home/honery/Documents/cursach/app/__init__.py:33]
2019-12-07 16:54:06,630 INFO: Microblog startup [in /home/honery/Documents/cursach/app/__init__.py:33]
2019-12-07 16:59:32,539 INFO: Microblog startup [in /home/honery/Documents/cursach/app/__init__.py:33]
2019-12-07 17:08:06,452 INFO: Microblog startup [in /home/honery/Documents/cursach/app/__init__.py:33]
2019-12-07 17:13:33,544 ERROR: Exception on /edit_profile [GET] [in /home/honery/Documents/cursach/.env/lib/python3.7/site-packages/flask/app.py:1891]
Traceback (most recent call last):
  File "/home/honery/Documents/cursach/.env/lib/python3.7/site-packages/flask/app.py", line 2446, in wsgi_app
    response = self.full_dispatch_request()
  File "/home/honery/Documents/cursach/.env/lib/python3.7/site-packages/flask/app.py", line 1951, in full_dispatch_request
    rv = self.handle_user_exception(e)
  File "/home/honery/Documents/cursach/.env/lib/python3.7/site-packages/flask/app.py", line 1820, in handle_user_exception
    reraise(exc_type, exc_value, tb)
  File "/home/honery/Documents/cursach/.env/lib/python3.7/site-packages/flask/_compat.py", line 39, in reraise
    raise value
  File "/home/honery/Documents/cursach/.env/lib/python3.7/site-packages/flask/app.py", line 1949, in full_dispatch_request
    rv = self.dispatch_request()
  File "/home/honery/Documents/cursach/.env/lib/python3.7/site-packages/flask/app.py", line 1935, in dispatch_request
    return self.view_functions[rule.endpoint](**req.view_args)
  File "/home/honery/Documents/cursach/.env/lib/python3.7/site-packages/flask_login/utils.py", line 261, in decorated_view
    return func(*args, **kwargs)
  File "/home/honery/Documents/cursach/app/routes.py", line 127, in edit_profile
    form.contact_info.data = current_user.contact_info
  File "/home/honery/Documents/cursach/.env/lib/python3.7/site-packages/werkzeug/local.py", line 348, in __getattr__
    return getattr(self._get_current_object(), name)
AttributeError: 'User' object has no attribute 'contact_info'
2019-12-07 17:14:09,926 ERROR: Exception on /edit_profile [GET] [in /home/honery/Documents/cursach/.env/lib/python3.7/site-packages/flask/app.py:1891]
Traceback (most recent call last):
  File "/home/honery/Documents/cursach/.env/lib/python3.7/site-packages/flask/app.py", line 2446, in wsgi_app
    response = self.full_dispatch_request()
  File "/home/honery/Documents/cursach/.env/lib/python3.7/site-packages/flask/app.py", line 1951, in full_dispatch_request
    rv = self.handle_user_exception(e)
  File "/home/honery/Documents/cursach/.env/lib/python3.7/site-packages/flask/app.py", line 1820, in handle_user_exception
    reraise(exc_type, exc_value, tb)
  File "/home/honery/Documents/cursach/.env/lib/python3.7/site-packages/flask/_compat.py", line 39, in reraise
    raise value
  File "/home/honery/Documents/cursach/.env/lib/python3.7/site-packages/flask/app.py", line 1949, in full_dispatch_request
    rv = self.dispatch_request()
  File "/home/honery/Documents/cursach/.env/lib/python3.7/site-packages/flask/app.py", line 1935, in dispatch_request
    return self.view_functions[rule.endpoint](**req.view_args)
  File "/home/honery/Documents/cursach/.env/lib/python3.7/site-packages/flask_login/utils.py", line 261, in decorated_view
    return func(*args, **kwargs)
  File "/home/honery/Documents/cursach/app/routes.py", line 127, in edit_profile
    form.contact_info.data = current_user.contact_info
  File "/home/honery/Documents/cursach/.env/lib/python3.7/site-packages/werkzeug/local.py", line 348, in __getattr__
    return getattr(self._get_current_object(), name)
AttributeError: 'User' object has no attribute 'contact_info'
2019-12-07 17:14:26,841 INFO: Microblog startup [in /home/honery/Documents/cursach/app/__init__.py:33]
